<?xml version="1.0" ?>
<robot name="myrobo">
    <link name="world" />
    <link name="base_link">
        <visual>
            <geometry>
                <box size=".2 .2 0.05" />
            </geometry>
            <material name="silver">
                <color rgba="0.75 0.75 0.75 1" />
            </material>
            <origin rpy="0 0 0" xyz="0 0 0.025" />
        </visual>
        <collision>
            <geometry>
                <box size=".2 .2 0.05" />
            </geometry>
            <origin rpy="0 0 0" xyz="0 0 0.025" />
        </collision>
        
<inertial>
            <mass value="0.1" />
            <inertia ixx="0.03" iyy="0.03" izz="0.03" ixy="0.0" ixz="0.0" iyz="0.0" />
        </inertial>

    </link>
    <joint name="fixed" type="fixed">
        <parent link="world" />
        <child link="base_link" />
    </joint>
    <link name="link1">
        <visual>
            <geometry>
                <box size=".05 .05 .4" />
            </geometry>
            <material name="silver">
                <color rgba="0.75 0.75 0.75 1" />
            </material>
            <origin rpy="0 0 0" xyz="0 0 0.2" />
        </visual>
        <collision>
            <geometry>
                <box size=".05 .05 .4" />
            </geometry>
            <origin rpy="0 0 0" xyz="0 0 0.2" />
        </collision>
        
<inertial>
            <mass value="0.1" />
            <inertia ixx="0.03" iyy="0.03" izz="0.03" ixy="0.0" ixz="0.0" iyz="0.0" />
        </inertial>

    </link>
    <joint name="joint1" type="continuous">
        <axis xyz="0 0 1" />
        <parent link="base_link" />
        <child link="link1" />
        <origin rpy="0 0 0" xyz="0 0 0.05" />
    </joint>
    <link name="link2">
        <visual>
            <geometry>
                <box size=".05 .35 .05" />
            </geometry>
            <material name="silver">
                <color rgba="0.75 0.75 0.75 1" />
            </material>
            <origin rpy="0 0 0" xyz="0 0.175 0.025" />
        </visual>
        <collision>
            <geometry>
                <box size=".05 .35 .05" />
            </geometry>
            <origin rpy="0 0 0" xyz="0 0.175 0.025" />
        </collision>
        
<inertial>
            <mass value="0.1" />
            <inertia ixx="0.03" iyy="0.03" izz="0.03" ixy="0.0" ixz="0.0" iyz="0.0" />
        </inertial>

    </link>
    <joint name="joint2" type="continuous">
        <axis xyz="1 0 0" />
        <parent link="link1" />
        <child link="link2" />
        <origin rpy="0 0 0" xyz="-0.05 0 0.375" />
    </joint>
    <link name="link3">
        <visual>
            <geometry>
                <box size=".35 .05 .05" />
            </geometry>
            <material name="silver">
                <color rgba="0.75 0.75 0.75 1" />
            </material>
            <origin rpy="0 0 0" xyz="0.175 0.025 0.025" />
        </visual>
        <collision>
            <geometry>
                <box size=".35 .05 .05" />
            </geometry>
            <origin rpy="0 0 0" xyz="0.175 0.025 0.025" />
        </collision>
        
<inertial>
            <mass value="0.1" />
            <inertia ixx="0.03" iyy="0.03" izz="0.03" ixy="0.0" ixz="0.0" iyz="0.0" />
        </inertial>

    </link>
    <joint name="joint3" type="continuous">
        <axis xyz="0 1 0" />
        <parent link="link2" />
        <child link="link3" />
        <origin rpy="0 0 0" xyz="0 0.35 0.025" />
    </joint>
    <link name="link4">
        <visual>
            <geometry>
                <box size=".05 -0.35 .05" />
            </geometry>
            <material name="silver">
                <color rgba="0.75 0.75 0.75 1" />
            </material>
            <origin rpy="0 0 0" xyz="0.025 -0.175 0.025" />
        </visual>
        <collision>
            <geometry>
                <box size=".05 -0.35 .05" />
            </geometry>
            <origin rpy="0 0 0" xyz="0.025 -0.175 0.025" />
        </collision>
        
<inertial>
            <mass value="0.1" />
            <inertia ixx="0.03" iyy="0.03" izz="0.03" ixy="0.0" ixz="0.0" iyz="0.0" />
        </inertial>

    </link>
    <joint name="joint4" type="continuous">
        <axis xyz="1 0 0" />
        <parent link="link3" />
        <child link="link4" />
        <origin rpy="0 0 0" xyz=".35 .05 .05" />
    </joint>
    <link name="link5">
        <visual>
            <geometry>
                <box size="0.05 0.05 .3" />
            </geometry>
            <material name="silver">
                <color rgba="0.75 0.75 0.75 1" />
            </material>
            <origin rpy="0 0 0" xyz="0.025 0.025 0.15" />
        </visual>
        <collision>
            <geometry>
                <box size="0.05 0.05 .3" />
            </geometry>
            <origin rpy="0 0 0" xyz="0.025 0.025 0.15" />
        </collision>
        
<inertial>
            <mass value="0.1" />
            <inertia ixx="0.03" iyy="0.03" izz="0.03" ixy="0.0" ixz="0.0" iyz="0.0" />
        </inertial>

    </link>
    <joint name="joint5" type="continuous">
        <axis xyz="0 1 0" />
        <parent link="link4" />
        <child link="link5" />
        <origin rpy="0 0 0" xyz=".025 -0.4 .05" />
    </joint>
    <link name="link6">
        <visual>
            <geometry>
                <cylinder length=".05" radius=".06" />
            </geometry>
            <material name="silver">
                <color rgba="0.75 0.75 0.75 1" />
            </material>
            <origin rpy="0 0 0" xyz="0 0 0.025" />
        </visual>
        <collision>
            <geometry>
                <cylinder length=".05" radius=".06" />
            </geometry>
            <origin rpy="0 0 0" xyz="0 0 0.025" />
        </collision>
        
<inertial>
            <mass value="0.1" />
            <inertia ixx="0.03" iyy="0.03" izz="0.03" ixy="0.0" ixz="0.0" iyz="0.0" />
        </inertial>

    </link>
    <joint name="joint6" type="continuous">
        <axis xyz="0 0 1" />
        <parent link="link5" />
        <child link="link6" />
        <origin rpy="0 0 0" xyz="0.025 .025 .3" />
    </joint>
    <link name="finger1">
        <visual>
            <geometry>
                <box size="0.01 0.01 .05" />
            </geometry>
            <material name="silver">
                <color rgba="0.75 0.75 0.75 1" />
            </material>
            <origin rpy="0 0 0" xyz="0.005 0.005 0.025 " />
        </visual>
        <collision>
            <geometry>
                <box size="0.01 0.01 .05" />
            </geometry>
            <origin rpy="0 0 0" xyz="0.005 0.005 0.025 " />
        </collision>
        
<inertial>
            <mass value="0.1" />
            <inertia ixx="0.03" iyy="0.03" izz="0.03" ixy="0.0" ixz="0.0" iyz="0.0" />
        </inertial>

    </link>
    <joint name="f_joint1" type="prismatic">
        <origin rpy="0 0 0" xyz="0 0 0.05" />
        <axis xyz="0 1 0" />
        <limit effort="100" lower="0.01" upper="0.020" velocity="1" />
        <parent link="link6" />
        <child link="finger1" />
        
        <dynamics damping="1" friction="1" />
    </joint>
    <link name="finger2">
        <visual>
            <geometry>
                <box size="0.01 0.01 .05" />
            </geometry>
            <material name="silver">
                <color rgba="0.75 0.75 0.75 1" />
            </material>
            <origin rpy="0 0 0" xyz="0.005 0.005 0.025 " />
        </visual>
        <collision>
            <geometry>
                <box size="0.01 0.01 .05" />
            </geometry>
            <origin rpy="0 0 0" xyz="0.005 0.005 0.025 " />
        </collision>
        
<inertial>
            <mass value="0.1" />
            <inertia ixx="0.03" iyy="0.03" izz="0.03" ixy="0.0" ixz="0.0" iyz="0.0" />
        </inertial>

    </link>
    <joint name="f_joint2" type="prismatic">
        <origin rpy="0 0 0" xyz="0 0 0.05" />
        <axis xyz="0 1 0" />
        <limit effort="100" lower="-0.010" upper="-0.02" velocity="1" />
        <mimic joint="f_joint1" multiplier="-1"  offset="0" />
        <parent link="link6" />
        <child link="finger2" />
       
        <dynamics damping="1" friction="1" />
    </joint>

    <gazebo>
	<plugin name="f_joint2_plugin" filename="libroboticsgroup_gazebo_mimic_joint_plugin.so">
	    <joint>f_joint1</joint>
	    <mimicJoint>f_joint2</mimicJoint>
	    <multiplier>-1</multiplier>
	</plugin>
    </gazebo>
</robot>
