<?xml version="1.0" ?>
<robot name="manipulator">
    <link name="world" />
    <!-- BASE LINK -->
    <link name="base_link">
        <visual>
            <origin rpy="0 0 0" xyz="0 0 0.01" />
            <geometry>
                <cylinder length="0.02" radius="0.5" />
            </geometry>
            <material name="White" />
        </visual>
        <collision>
            <origin rpy="0 0 0" xyz="0 0 0.01" />
            <geometry>
                <cylinder length="0.02" radius="0.5" />
            </geometry>
        </collision>
        
<inertial>
            <mass value="0.1" />
            <inertia ixx="0.03" iyy="0.03" izz="0.03" ixy="0.0" ixz="0.0" iyz="0.0" />
        </inertial>

    </link>
    <!-- joint -->
    <joint name="fixed" type="fixed">
        <parent link="world" />
        <child link="base_link" />
    </joint>
    <!-- LINK 1 -->
    <link name="link1">
        <visual>
            <origin rpy="0 0 0" xyz="0 0 0.05" />
            <!-- linknte paathi distance -->
            <geometry>
                <cylinder length="0.10" radius="0.10" />
            </geometry>
            <material name="Blue" />
        </visual>
        <collision>
            <origin rpy="0 0 0" xyz="0 0 0.05" />
            <geometry>
                <cylinder length="0.10" radius="0.10" />
            </geometry>
        </collision>
        
<inertial>
            <mass value="0.1" />
            <inertia ixx="0.03" iyy="0.03" izz="0.03" ixy="0.0" ixz="0.0" iyz="0.0" />
        </inertial>

    </link>
    <!-- JOINT 1 -->
    <joint name="joint1" type="continuous">
        <origin rpy="0 0 0" xyz="0 0 0.01" />
        <!--parent linknte distance -->
        <parent link="base_link" />
        <child link="link1" />
        <axis xyz="0 0 1" />
    </joint>
    <!-- LINK 2 -->
    <link name="link2">
        <visual>
            <origin rpy="0 0 0" xyz="0 0 0.15" />
            <geometry>
                <cylinder length="0.30" radius="0.03" />
            </geometry>
            <material name="Blue" />
        </visual>
        <collision>
            <origin rpy="0 0 0" xyz="0 0 0.15" />
            <geometry>
                <cylinder length="0.30" radius="0.03" />
            </geometry>
        </collision>
        
<inertial>
            <mass value="0.1" />
            <inertia ixx="0.03" iyy="0.03" izz="0.03" ixy="0.0" ixz="0.0" iyz="0.0" />
        </inertial>

    </link>
    <!-- JOINT 2 -->
    <joint name="joint2" type="revolute">
        <origin rpy="0 0 0" xyz="0 0 0.08" />
        <parent link="link1" />
        <child link="link2" />
        <axis xyz="0 1 0" />
        <limit lower="-1.57" upper="1.57" effort="100" velocity="1" />
        <dynamics damping="0.01" friction="0.01" />
    </joint>
    <!-- LINK 3 -->
    <link name="link3">
        <visual>
            <origin rpy="0 0 0" xyz="0 0 0.15" />
            <geometry>
                <cylinder length="0.30" radius="0.03" />
            </geometry>
            <material name="Blue" />
        </visual>
        <collision>
            <origin rpy="0 0 0" xyz="0 0 0.15" />
            <geometry>
                <cylinder length="0.30" radius="0.03" />
            </geometry>
        </collision>
        
<inertial>
            <mass value="0.1" />
            <inertia ixx="0.03" iyy="0.03" izz="0.03" ixy="0.0" ixz="0.0" iyz="0.0" />
        </inertial>

    </link>
    <!-- JOINT 3 -->
    <joint name="joint3" type="revolute">
        <origin rpy="0 0 0" xyz="0 0 0.28" />
        <parent link="link2" />
        <child link="link3" />
        <axis xyz="0 1 0" />
        <limit lower="-2.57" upper="2.57" effort="100" velocity="1" />
        <dynamics damping="0.01" friction="0.01" />
    </joint>
    <!-- LINK 4 -->
    <link name="link4">
        <visual>
            <origin rpy="0 0 0" xyz="0 0 0.05" />
            <geometry>
                <box size="0.03 0.03 0.1" />
            </geometry>
            <material name="Blue" />
        </visual>
        <collision>
            <origin rpy="0 0 0" xyz="0 0 0.05" />
            <geometry>
                <box size="0.03 0.03 0.1" />
            </geometry>
        </collision>
        
<inertial>
            <mass value="0.1" />
            <inertia ixx="0.03" iyy="0.03" izz="0.03" ixy="0.0" ixz="0.0" iyz="0.0" />
        </inertial>

    </link>
    <!-- JOINT 4 -->
    <joint name="joint4" type="revolute">
        <origin rpy="0 0 0" xyz="0 0 0.28" />
        <parent link="link3" />
        <child link="link4" />
        <axis xyz="0 0 1" />
        <limit lower="-3.14" upper="3.14" effort="100" velocity="1" />
        <dynamics damping="0.01" friction="0.01" />
    </joint>
    <!-- LINK 5 -->
    <link name="link5">
        <visual>
            <origin rpy="0 0 0" xyz="0 0 0.05" />
            <geometry>
                <box size="0.03 0.03 0.1" />
            </geometry>
            <material name="Blue" />
        </visual>
        <collision>
            <origin rpy="0 0 0" xyz="0 0 0.05" />
            <geometry>
                <box size="0.03 0.03 0.1" />
            </geometry>
        </collision>
        
<inertial>
            <mass value="0.1" />
            <inertia ixx="0.03" iyy="0.03" izz="0.03" ixy="0.0" ixz="0.0" iyz="0.0" />
        </inertial>

    </link>
    <!-- JOINT 5 -->
    <joint name="joint5" type="revolute">
        <origin rpy="0 0 0" xyz="0 0 0.08" />
        <parent link="link4" />
        <child link="link5" />
        <axis xyz="0 1 0" />
        <limit lower="-2.57" upper="2.57" effort="100" velocity="1" />
        <dynamics damping="0.01" friction="0.01" />
    </joint>
    <!-- LINK 6 -->
    <link name="link6">
        <visual>
            <origin rpy="0 0 0" xyz="0 0 0.05" />
            <geometry>
                <cylinder length="0.10" radius="0.04" />
            </geometry>
            <material name="Blue" />
        </visual>
        <collision>
            <origin rpy="0 0 0" xyz="0 0 0.05" />
            <geometry>
                <cylinder length="0.10" radius="0.04" />
            </geometry>
        </collision>
        
<inertial>
            <mass value="0.1" />
            <inertia ixx="0.03" iyy="0.03" izz="0.03" ixy="0.0" ixz="0.0" iyz="0.0" />
        </inertial>

    </link>
    <!-- JOINT 6 -->
    <joint name="joint6" type="revolute">
        <origin rpy="0 0 0" xyz="0 0 0.08" />
        <parent link="link5" />
        <child link="link6" />
        <axis xyz="1 0 0" />
        <limit lower="-2.57" upper="2.57" effort="100" velocity="1" />
        <dynamics damping="0.01" friction="0.01" />
    </joint>
    <!--FINGER LINK 2 -->
    <link name="fingerlink2">
        <visual>
            <geometry>
                <box size="0.01 0.01 .05" />
            </geometry>
            <material name="silver">
                <color rgba="0.75 0.75 0.75 1" />
            </material>
            <origin rpy="0 0 0" xyz="0.005 0.005 0.025 " />
        </visual>
        <collision>
            <geometry>
                <box size="0.01 0.01 .05" />
            </geometry>
            <origin rpy="0 0 0" xyz="0.005 0.005 0.025" />
        </collision>
        
<inertial>
            <mass value="0.1" />
            <inertia ixx="0.03" iyy="0.03" izz="0.03" ixy="0.0" ixz="0.0" iyz="0.0" />
        </inertial>

    </link>
    <!-- FINGER JOINT 2 -->
    <joint name="fingerjoint2" type="prismatic">
        <origin rpy="0 0 0" xyz="0 0.025 0.1" />
        <parent link="link6" />
        <child link="fingerlink2" />
        <axis xyz="0 1 0" />
        <limit lower="0.01" upper="0.04" effort="100" velocity="1" />
    
    </joint>
    <!--FINGER LINK 1 -->
    <link name="fingerlink1">
        <visual>
            <geometry>
                <box size="0.01 0.01 .05" />
            </geometry>
            <material name="silver">
                <color rgba="0.75 0.75 0.75 1" />
            </material>
            <origin rpy="0 0 0" xyz="0.005 0.005 0.025 " />
        </visual>
        <collision>
            <geometry>
                <box size="0.01 0.01 .05" />
            </geometry>
            <origin rpy="0 0 0" xyz="0.005 0.005 0.025 " />
        </collision>
        
<inertial>
            <mass value="0.1" />
            <inertia ixx="0.03" iyy="0.03" izz="0.03" ixy="0.0" ixz="0.0" iyz="0.0" />
        </inertial>

    </link>
    <!-- FINGER JOINT 1 -->
    <joint name="fingerjoint1" type="prismatic">
        <origin rpy="0 0 0" xyz="0 -0.025 0.1" />
        <parent link="link6" />
        <child link="fingerlink1" />
        <axis xyz="0 1 0" />
        <limit lower="-0.06" upper="0" effort="100" velocity="1" />
        <mimic joint="fingerjoint2" multiplier="-1.0" offset="0" />
    
    </joint>
<gazebo>
        <plugin name="fingerjoint2_plugin" filename="libroboticsgroup_gazebo_mimic_joint_plugin.so">
            <joint>fingerjoint1</joint>
            <mimicJoint>fingerjoint2</mimicJoint>
            <multiplier>-1</multiplier>
        </plugin>
    </gazebo>
    
    
<transmission name="trans_joint1">
        <type>transmission_interface/SimpleTransmission</type>
        <joint name="joint1">
            <hardwareInterface>hardware_interface/PositionJointInterface</hardwareInterface>
        </joint>
        <actuator name="joint1_motor">
            <hardwareInterface>hardware_interface/PositionJointInterface</hardwareInterface>
            <mechanicalReduction>1</mechanicalReduction>
        </actuator>
    </transmission>
    <transmission name="trans_joint2">
        <type>transmission_interface/SimpleTransmission</type>
        <joint name="joint2">
            <hardwareInterface>hardware_interface/PositionJointInterface</hardwareInterface>
        </joint>
        <actuator name="joint2_motor">
            <hardwareInterface>hardware_interface/PositionJointInterface</hardwareInterface>
            <mechanicalReduction>1</mechanicalReduction>
        </actuator>
    </transmission>
    <transmission name="trans_joint3">
        <type>transmission_interface/SimpleTransmission</type>
        <joint name="joint3">
            <hardwareInterface>hardware_interface/PositionJointInterface</hardwareInterface>
        </joint>
        <actuator name="joint3_motor">
            <hardwareInterface>hardware_interface/PositionJointInterface</hardwareInterface>
            <mechanicalReduction>1</mechanicalReduction>
        </actuator>
    </transmission>
    <transmission name="trans_joint4">
        <type>transmission_interface/SimpleTransmission</type>
        <joint name="joint4">
            <hardwareInterface>hardware_interface/PositionJointInterface</hardwareInterface>
        </joint>
        <actuator name="joint4_motor">
            <hardwareInterface>hardware_interface/PositionJointInterface</hardwareInterface>
            <mechanicalReduction>1</mechanicalReduction>
        </actuator>
    </transmission>
    <transmission name="trans_joint5">
        <type>transmission_interface/SimpleTransmission</type>
        <joint name="joint5">
            <hardwareInterface>hardware_interface/PositionJointInterface</hardwareInterface>
        </joint>
        <actuator name="joint5_motor">
            <hardwareInterface>hardware_interface/PositionJointInterface</hardwareInterface>
            <mechanicalReduction>1</mechanicalReduction>
        </actuator>
    </transmission>
    <transmission name="trans_joint6">
        <type>transmission_interface/SimpleTransmission</type>
        <joint name="joint6">
            <hardwareInterface>hardware_interface/PositionJointInterface</hardwareInterface>
        </joint>
        <actuator name="joint6_motor">
            <hardwareInterface>hardware_interface/PositionJointInterface</hardwareInterface>
            <mechanicalReduction>1</mechanicalReduction>
        </actuator>
    </transmission>
    <transmission name="trans_fingerjoint2">
        <type>transmission_interface/SimpleTransmission</type>
        <joint name="fingerjoint2">
            <hardwareInterface>hardware_interface/EffortJointInterface</hardwareInterface>
        </joint>
        <actuator name="fingerjoint2_motor">
            <hardwareInterface>hardware_interface/EffortJointInterface</hardwareInterface>
            <mechanicalReduction>1</mechanicalReduction>
        </actuator>
    </transmission>
    <transmission name="trans_fingerjoint1">
        <type>transmission_interface/SimpleTransmission</type>
        <joint name="fingerjoint1">
            <hardwareInterface>hardware_interface/EffortJointInterface</hardwareInterface>
        </joint>
        <actuator name="fingerjoint1_motor">
            <hardwareInterface>hardware_interface/EffortJointInterface</hardwareInterface>
            <mechanicalReduction>1</mechanicalReduction>
        </actuator>
    </transmission>
    <gazebo>
        <plugin name="gazebo_ros_control" filename="libgazebo_ros_control.so">
            <robotNamespace>/</robotNamespace>
        </plugin>
    </gazebo>
</robot>
